Workbook
Name DOLNOŚLĄSKIE: listy!$A$2:$A$31
Name KUJAWSKO_POMORSKIE: listy!$B$2:$B$24
Name LUBELSKIE: listy!$C$2:$C$25
Name LUBUSKIE: listy!$D$2:$D$15
Name ŁÓDZKIE: listy!$E$2:$E$25
Name MAŁOPOLSKIE: listy!$F$2:$F$24
Name MAZOWIECKIE: listy!$G$2:$G$43
Name OPOLSKIE: listy!$H$2:$H$13
Name PODKARPACKIE: listy!$I$2:$I$26
Name PODLASKIE: listy!$J$2:$J$18
Name POMORSKIE: listy!$K$2:$K$21
Name ŚLĄSKIE: listy!$L$2:$L$37
Name ŚWIĘTOKRZYSKIE: listy!$M$2:$M$15
Name WARMIŃSKO_MAZURSKIE: listy!$N$2:$N$22
Name WIELKOPOLSKIE: listy!$O$2:$O$36
Name ZACHODNIOPOMORSKIE: listy!$P$2:$P$22

Sheet Dane podstawowe
C2: Plik dla WUP
C4: Dane podstawowe
C6: WOJEWÓDZTWO | D6: MAZOWIECKIE
C7: OKRES SPRAWOZDAWCZY - MIESIĄC | D7: Marzec
C8: OKRES SPRAWOZDAWCZY - ROK | D8: 2020
C13: Osoba do kontaktu z WUP | D13: Hubert Samul | E13: h.samul@wup.mazowsze.pl | F13: 602349485
D14: Imię i nazwisko | E14: e-mail | F14: tel.
C19: Objaśnienia do wypełniania plików
C21: 1. Proszę wybrać z listy rozwijanej powyżej województwo i okres sprawozdawczy (miesiąci rok) za jaki przekazywane są dane
D22: →
C25: 2. Proszę uzupełnić pole "osoba do kontaktu z WUP"
C29: 3. Po wybraniu w arkuszu "dane podstawowe" - województwa i okresu sprawozdawczego, w każdym kolejnym arkuszu informacje te zostaną automatycznie wyświetlone
C36: 5. W kolumnie "sekcja PKD" prosimy wpisać tę, w której firma dokonuje zwolnienia

Sheet Zgłoszenia w miesiącu
B2: Województwo: | C2: ='Dane podstawowe'!$D$6 -> MAZOWIECKIE | D2: ='Dane podstawowe'!$D$7 -> Marzec | E2: ='Dane podstawowe'!$D$8 -> 2020
B4: Zgłoszenia zwolnień z przyczyn dotyczących zakładu pracy (w miesiącu sprawozdawczym)
B7: Powiat | C7: Nazwa zakładu pracy | D7: REGON zakładu pracy (14-cyfrowy) | E7: Sekcja PKD | F7: Liczba osób zgłoszonych do zwolnienia | G7: Planowany termin dokonania zwolnień
B8: zgłoszenia w miesiącu sprawozdawczym
B10: ='[1]Dane podstawowe'!$D$7 -> piaseczyński | C10: Camaieu Polska Sp. z o.o. | D10: REGON016318511 | E10: 5242 | F10: 5 | G10: 31.03.2020-30.06.2020 | I10: 5
B11: przasnyski | C11: KROSS USŁUGI Sp z o o ,ul.Leszno 46,06-300 Przasnysz | D11: 38514934700000 | E11: 82.99Z | F11: 90 | G11: 27.03.2020 - 31.05.2020 | I11: 90
B12: przasnyski | C12: KROSS LOGISTYKA,ul.Leszno 46,06-300 Przasnysz | D12: 36968234400000 | E12: 52.10B | F12: 20 | G12: 27.03.2020 - 31.05.2020 | I12: 20
B13: przasnyski | C13: KROSS SA,ul.Leszno 46,06-300 Przsnysz | D13: 38514934700000 | E13: 82.99Z | F13: 41 | G13: 27.03.2020 - 31.05.2020 | I13: 41
B14: przasnyski | C14: ZIPP Skutery Sp z o.o , ul.Leszno 40, 06-300 Przasnysz | D14: 14114202100000 | E14: 45.40Z | F14: 45 | G14: 30.03.2020-31.10.2020 | I14: 45
B15: ='[2]Dane podstawowe'!$D$7 -> m. Radom | C15: PPH SMAKOSZ Mariusz Orłowski | D15: 671934409 | E15: 1085Z | F15: 35 | G15: 44012 | I15: 35
B16: m. Siedlce | C16: NEST BANK SPÓŁKA AKCYJNA | D16: 1092812500000 | E16: 6419Z | F16: 1 | G16: 31.03.2020 | I16: 1
B17: m. Siedlce | C17: NEST BANK SPÓŁKA AKCYJNA | D17: 1092812500000 | E17: 6419Z | F17: 4 | G17: absencja | I17: 4
B18: m. Siedlce | C18: PROVIDENT POLSKA SPÓŁKA AKCYJNA | D18: 1199488000000 | E18: 6492Z | F18: 5 | G18: 30.06.2020 | I18: 5
B19: warszawski zachodni | C19: CAMAIEU POLSKA SP. Z O.O. | D19: 16318511 | E19: 4771 | F19: 5 | G19: do 30.06.2020 | I19: 5
B20: m. Warszawa | C20: PZ Cussons Polska S.A. w likwidacji ul. Chociska 17 00-791 Warszawa | D20: 017471692 | E20: 4645Z | F20: 47 | G20: 03-06.2020 r. | I20: 47
B21: m. Warszawa | C21: Teren Operations Polnad sp. z o.o. ul. Złota 59 00-120 Warszawa | D21: 363808815 | E21: 7010Z | F21: 33 | G21: 03-04.2020 r. | I21: 33
B22: m. Warszawa | C22: Formfarm Sp. z o.o ul. Chełmżyńska 219 04-458 Warszawa | D22: 015714593 | E22: 4646Z | F22: 24 Płock | G22: 03-06.2020 r. | I22: 24
B23: m. Warszawa | C23: MURATOR EXPO Sp. z o.o. ul. Dęblińska 6 04-187 Warszawa | D23: 014837230 | E23: 8230Z | F23: 28 | G23: 03-06.2020 r. | I23: 28
B24: m. Warszawa | C24: Carlson Wagonit Ecenter Polska Sp. z o.o. ul. Domaniewska 41 02-672 Warszawa | D24: 277700010 | E24: 7990C | F24: 39 | G24: 03-04.2020 r. | I24: 39
B25: m. Warszawa | C25: Imperial Cinepix Sp. z o.o. ul. Grójecka 208 02-390 Warszawa | D25: 011167237 | E25: 5913Z | F25: 26 | G25: 03-06.2020 r. | I25: 26
B26: m. Warszawa | C26: MS Sales Support Sp. z o.o. ul. Włodarzewska 45A 02-384 Warszawa | D26: 368972318 | E26: 7311Z | F26: 25 | G26: 03-06.2020 r. | I26: 25
B27: m. Warszawa | C27: Booksy International Sp. z o.o. ul. Łucka 2/4/6 lok U4 00-845 Warszawa | D27: 147315920 | E27: 6399Z | F27: 40 | G27: 03-06.2020 r. | I27: 40
I28: =SUM(I10:I27) -> 513

Sheet Zgłoszenia na koniec miesiaca
B2: Województwo: | C2: MAZOWIECKIE | D2: ='Dane podstawowe'!$D$7 -> Marzec | E2: 2020
B4: Zgłoszenia zwolnień z przyczyn dotyczących zakładu pracy (w końcu miesiąca sprawozdawczego)
B7: Powiat | C7: Nazwa zakładu pracy | D7: REGON zakładu pracy (14-cyfrowy) | E7: Sekcja PKD | F7: Liczba osób zgłoszonych do zwolnienia | G7: Planowany termin dokonania zwolnień
B9: zgłoszenia aktualne według stanu w końcu miesiąca sprawozdawczego
B11: ='[3]Dane podstawowe'!$D$7 -> gostyniński | C11: ELGO Light Industries S.A. | D11: 14046491700000 | E11: 2740z | F11: 1 | G11: brak danych | I11: 1
B12: ='[4]Dane podstawowe'!$D$7 -> nowodworski | C12: JAN-POL BIELIŃSCY SPÓŁKA Z OGRANICZONĄ ODPOWIEDZIALNOŚCIĄ | D12: 36231484400000 | E12: 2733Z | F12: 56 | G12: do 31.03.2020 | I12: 56
B13: ='[5]Dane podstawowe'!$D$7 -> m. Ostrołęka | C13: Stora Enso Poland S.A. | D13: 550412627 | E13: 1712Z | F13: 130 | G13: do 31.12.2020 | I13: 130
B14: ='[1]Dane podstawowe'!$D$7 -> piaseczyński | C14: Camaieu Polska Sp. z o.o. | D14: REGON016318511 | E14: 5242 | F14: 5 | G14: 31.03.2020-30.06.2020 | I14: 5
B15: przasnyski | C15: KROSS USŁUGI Sp z o o ,ul.Leszno 46,06-300 Przasnysz | D15: 38514934700000 | E15: 82.99Z | F15: 90 | G15: 27.03.2020 - 31.05.2020 | I15: 90
B16: przasnyski | C16: KROSS LOGISTYKA,ul.Leszno 46,06-300 Przasnysz | D16: 36968234400000 | E16: 52.10B | F16: 20 | G16: 27.03.2020 - 31.05.2020 | I16: 20
B17: przasnyski | C17: KROSS SA,ul.Leszno 46,06-300 Przsnysz | D17: 38514934700000 | E17: 82.99Z | F17: 41 | G17: 27.03.2020 - 31.05.2020 | I17: 41
B18: przasnyski | C18: ZIPP Skutery Sp z o.o , ul.Leszno 40, 06-300 Przasnysz | D18: 14114202100000 | E18: 45.40Z | F18: 45 | G18: 30.03.2020-31.10.2020 | I18: 45
B19: ='[2]Dane podstawowe'!$D$7 -> m. Radom | C19: PPH SMAKOSZ Mariusz Orłowski | D19: 671934409 | E19: 1085Z | F19: 35 | G19: 44012 | I19: 35
B20: m. Siedlce | C20: NEST BANK SPÓŁKA AKCYJNA | D20: 1092812500000 | E20: 6419Z | F20: 4 | G20: absencja | I20: 4
B21: m. Siedlce | C21: PROVIDENT POLSKA SPÓŁKA AKCYJNA | D21: 1199488000000 | E21: 6492Z | F21: 5 | G21: 30.06.2020 | I21: 5
B22: warszawski zachodni | C22: CAMAIEU POLSKA SP. Z O.O. | D22: 16318511 | E22: 4771 | F22: 5 | G22: do 30.06.2020 | I22: 5
B23: żuromiński | C23: "TOMIC" Spółka Akcyjna | D23: 130335607 | E23: 2751Z | F23: 8 | G23: 31.01.2020 | I23: 8
B24: m. Warszawa | C24: Topsil Semicondutors Sp. zo.o. ul. Wolczyńska 133 01-919 Warszawa | D24: 362138710 | E24: 2611Z | F24: 18 | G24: 01-12.2019 r. | I24: 18
B25: m. Warszawa | C25: PKO BP S.A. ul. Puławska 15 02-515 Warszawa | D25: 16298263 | E25: 6419Z | F25: 608 (Cała Polska) | G25: 02- 12.2019 r. | I25: 608
B26: m. Warszawa | C26: Bank Polska Kasa Opieki Spółka Akcyjna ul. Grzybowska 53/57 00-950 Warszawa | D26: 000010205 | E26: 6419Z | F26: 584 wypowiedzenia definitywne + wypowiedzenia zmieniające warunki pracy i płacy (Cała Polska) | G26: 04-10.2019 r. | I26: 584
B27: m. Warszawa | C27: Castorama Polska Sp. z o.o. Oddział I w Warszawie ul. Krakowiaków 78 02-255 Warszawa | D27: 10817199 | E27: 4752Z | F27: 84 | G27: 06.2019 r. -12.2020 r. | I27: 84
B28: m. Warszawa | C28: Idea Bank S.A. ul. Przyokopowa 33 01-208 Warszawa | D28: 011063638 | E28: 6419Z | F28: 514 wypowiedzenia definitywne + wypowiedzenia zmieniające warunki pracy i płacy (Cała Polska) | G28: 06-12.2019 r. | I28: 514
B29: m. Warszawa | C29: Svenska Handelsbanken AB ( Spółka Akcyjna) Oddział w Polsce ul. Wołowska 22 02-675 Warszawa | D29: 15833145 | E29: 6419Z | F29: 36 | G29: 07.2019 r. -08.2020 r. | I29: 36
B30: m. Warszawa | C30: T-MOBILE Polska S.A. ul. Marynarska 12 02-674 Warszawy | D30: 011417295 | E30: 6120Z | F30: 294 wypowiedzenia definitywne + wypowiedzenia zmieniające warunki pracy i płacy (Cała Polska) | G30: 09.2019 r. -03.2020 r. | I30: 294
B31: m. Warszawa | C31: GE Power sp. zo.o. w Warszawie ul. Inflancka 4 00-189 Warszawa | D31: 2790450 | E31: 2811 | F31: 58 | G31: 11.2019 r. - 12.2020 r. | I31: 58
B32: m. Warszawa | C32: Pierre Fabre Dermo-Cosmetique Polska Sp. z o.o. ul. Belwederska 20/22 00-762 Warszawa | D32: 16262609 | E32: 4645Z | F32: 27 wypowiedzenia definitywne + wypowiedzenia zmieniające warunki pracy i płacy | G32: 11.2019 r. - 12.2020 r. | I32: 27
B33: m. Warszawa | C33: Orange Polska S.A. Al. Jerozolimskie 160 02-326 Warszawa | D33: 12100784 | E33: 6110 | F33: 1250 wypowiedzenia definitywne + wypowiedzenia zmieniające (Cała Polska) | G33: 12.2019 r.-12.2020 r. | I33: 1250
B34: m. Warszawa | C34: CA Sp. z o.o. | D34: 012248245 | E34: 6201Z | F34: 11 | G34: 12.2019 r.-03.2020 r. | I34: 11
B35: m. Warszawa | C35: Agito Sp. z o.o. ul. Inflancka 4 a 00-189 Warszawa | D35: 15206780 | E35: 4791Z | F35: 19 | G35: 01 - 04.2020 r. | I35: 19
B36: m. Warszawa | C36: Bank Millennium S.A. ul. Stanisława Żaryna 2A 02-593 Warszawa | D36: 1379728 | E36: 6419Z | F36: 260 (Cała Polska) | G36: 01 - 04.2020 r. | I36: 260
B37: m. Warszawa | C37: Provident Polska S.A. ul. Inflancka 4a 03-189 Warszawa | D37: 11994880 | E37: 6492Z | F37: 113 (Cała Polska) | G37: 01 - 04.2020 r. | I37: 113
B38: m. Warszawa | C38: Takeda Pharma Sp. z o.o. ul. Prosta 68 00-838 Warszawa | D38: 12765897 | E38: 2120Z | F38: 32 | G38: 01 - 03.2020 r. | I38: 32
B39: m. Warszawa | C39: Nest Bank S.A. ul. Wołoska 24 02-675 Warszawa | D39: 010928125 | E39: 6419Z | F39: 53 (Cała Polska) | G39: 01 - 03.2020 r. | I39: 53
B40: m. Warszawa | C40: Souter Holdings Poland Sp. z o.o. Al. Niepodległości 18 02-653 Warszawa | D40: 141990677 | E40: 4939Z | F40: 163 (Cała Polska) | G40: 01 - 04.2020 r. | I40: 163
B41: m. Warszawa | C41: Alpega Poland Sp. z o.o ul. Przyokopowa 33 01-208 Warszawa | D41: 13036781 | E41: 5829Z | F41: 23 | G41: 01 - 03.2020 r. | I41: 23
B42: m. Warszawa | C42: Hermes Energy ul. Postępu 18 a 02-676 Warszawa | D42: 147154380 | E42: 3523Z | F42: 66 | G42: 02 - 04.2020 r. | I42: 66
B43: m. Warszawa | C43: PKO BP S.A. ul. Puławska 15 02-515 Warszawa | D43: 16298263 | E43: 6419Z | F43: 550 (Cała Polska) | G43: 02- 12.2020 r. | I43: 550
B44: m. Warszawa | C44: Bank Polska Kasa Opieki Spółka Akcyjna ul. Grzybowska 53/57 00-950 Warszawa | D44: 000010205 | E44: 6419Z | F44: 1200 wypowiedzenia definitywne + 1350 wypowiedzenia zmieniające warunki pracy i płacy (Cała Polska) | G44: 02-10.2020 r. | I44: =1200+ 1350 -> 2550
B45: m. Warszawa | C45: Getin Noble Bank Polska S.A. ul. Przyokopowa 33 01-208 Warszawa | D45: 141334039 | E45: 6419Z | F45: 250 | G45: 02-06.2020 r. | I45: 250
B46: m. Warszawa | C46: Przedsiębiorstwo Państwowe "Porty Lotnicze" ul. Żwirki i Wigury 1 00-906 Warszawa | D46: 000126652 | E46: 6323 | F46: 255 wypowiedzenia zmieniające warunki pracy i płacy | G46: 02-06.2020 r. | I46: 255
...

Sheet Zwolnienia
B2: Województwo: | C2: ='Dane podstawowe'!$D$6 -> MAZOWIECKIE | D2: ='Dane podstawowe'!$D$7 -> Marzec | E2: ='Dane podstawowe'!D8 -> 2020
B4: Zwolnienia z przyczyn dotyczących zakładu pracy (w miesiąc sprawozdawczym)
B7: Powiat | C7: Nazwa zakładu pracy | D7: REGON zakładu pracy (14-cyfrowy) | E7: Sekcja PKD | F7: Liczba osób zwolnionych z przyczyn dotyczących zakładu pracy na podstawie wcześniejszych zgłoszeń
B8: zwolnienia w miesiącu sprawozdawczym
B9: ='[4]Dane podstawowe'!$D$7 -> nowodworski | C9: JAN-POL BIELIŃSCY SPÓŁKA Z OGRANICZONĄ ODPOWIEDZIALNOŚCIĄ | D9: 36231484400000 | E9: 2733Z | F9: 56 | H9: 56
B10: ='[7]Dane podstawowe'!$D$7 -> gostyniński | C10: ELGO Light Industries S.A. | D10: 14046491700000 | E10: 2740z | F10: 2 | H10: 2
B11: m. Siedlce | C11: NEST BANK SPÓŁKA AKCYJNA | D11: 1092812500000 | E11: 6419Z | F11: 1 | H11: 1
B12: ='[6]Dane podstawowe'!$D$7 -> żuromiński | C12: "TOMIC" Spółka Akcyjna | D12: 130335607 | E12: 2751Z | F12: 1 | H12: 1
B13: m. Warszawa | C13: T-MOBILE Polska S.A. ul. Marynarska 12 02-674 Warszawy | D13: 011417295 | E13: 6120Z | F13: 28 | H13: 28
B14: m. Warszawa | C14: PRAXIS INVENT spółka z ograniczoną odpowiedzialnością spółka komandytowa | D14: 362856893 | E14: 4690Z | F14: 47 | H14: 47
B15: m. Warszawa | C15: Agito Sp. z o.o. ul. Inflancka 4 a 00-189 Warszawa | D15: 15206780 | E15: 4791Z | F15: 3 | H15: 3
B16: m. Warszawa | C16: Nest Bank S.A. ul. Wołoska 24 02-675 Warszawa | D16: 010928125 | E16: 6419Z | F16: 111 | H16: 111
B17: m. Warszawa | C17: CDP Sp. z o.o ul. Jagiellońska 88 00-992 Warszawa | D17: 016103851 | E17: 5821Z | F17: 22 | H17: 22
B18: m. Warszawa | C18: Alpega Poland Sp. z o.o ul. Przyokopowa 33 01-208 Warszawa | D18: 13036781 | E18: 5829Z | F18: 9 | H18: 9
H19: =SUM(H9:H18) -> 280

Sheet Zwolnienia monitorowane
B2: Województwo: | C2: ='Dane podstawowe'!$D$6 -> MAZOWIECKIE | D2: ='Dane podstawowe'!$D$7 -> Marzec | E2: ='Dane podstawowe'!D8 -> 2020
B4: Zwolnienia monitorowane (w miesiącu sprawozdawczym)
B7: Powiat | C7: Nazwa zakładu pracy | D7: REGON zakładu pracy (14-cyfrowy) | E7: Sekcja PKD | F7: Liczba osób objętych programem zwolnień | G7: Działania realizowane w ramach programu | H7: Planowany termin dokonania zwolnień
B8: zwolnienia monitorowane w miesiącu sprawozdawczym

Sheet listy
A1: DOLNOŚLĄSKIE | B1: KUJAWSKO-POMORSKIE | C1: LUBELSKIE | D1: LUBUSKIE | E1: ŁÓDZKIE | F1: MAŁOPOLSKIE | G1: MAZOWIECKIE | H1: OPOLSKIE | I1: PODKARPACKIE | J1: PODLASKIE | K1: POMORSKIE | L1: ŚLĄSKIE | M1: ŚWIĘTOKRZYSKIE | N1: WARMIŃSKO-MAZURSKIE | O1: WIELKOPOLSKIE | P1: ZACHODNIOPOMORSKIE | R1: 1 | S1: publiczny | T1: Styczeń | U1: 2019
A2: bolesławiecki | B2: aleksandrowski | C2: bialski | D2: gorzowski | E2: bełchatowski | F2: bocheński | G2: białobrzeski | H2: brzeski | I2: bieszczadzki | J2: augustowski | K2: bytowski | L2: będziński | M2: buski | N2: bartoszycki | O2: chodzieski | P2: białogardzki | R2: 2 | S2: prywatny | T2: Luty | U2: 2020
A3: dzierżoniowski | B3: brodnicki | C3: biłgorajski | D3: krośnieński | E3: kutnowski | F3: brzeski | G3: ciechanowski | H3: głubczycki | I3: brzozowski | J3: białostocki | K3: chojnicki | L3: bielski | M3: jędrzejowski | N3: braniewski | O3: czarnkowsko-trzcianecki | P3: choszczeński | T3: Marzec | U3: 2021
A4: głogowski | B4: bydgoski | C4: chełmski | D4: międzyrzecki | E4: łaski | F4: chrzanowski | G4: garwoliński | H4: kędzierzyńsko-kozielski | I4: dębicki | J4: bielski | K4: człuchowski | L4: cieszyński | M4: kazimierski | N4: działdowski | O4: gnieźnieński | P4: drawski | T4: Kwiecień | U4: 2022
A5: górowski | B5: chełmiński | C5: hrubieszowski | D5: nowosolski | E5: łęczycki | F5: dąbrowski | G5: gostyniński | H5: kluczborski | I5: jarosławski | J5: grajewski | K5: gdański | L5: częstochowski | M5: kielecki | N5: elbląski | O5: gostyński | P5: goleniowski | T5: Maj | U5: 2023
A6: jaworski | B6: golubsko-dobrzyński | C6: janowski | D6: słubicki | E6: łowicki | F6: gorlicki | G6: grodziski | H6: krapkowicki | I6: jasielski | J6: hajnowski | K6: kartuski | L6: gliwicki | M6: konecki | N6: ełcki | O6: grodziski | P6: gryficki | T6: Czerwiec | U6: 2024
A7: jeleniogórski | B7: grudziądzki | C7: krasnostawski | D7: strzelecko-drezdenecki | E7: łódzki wschodni | F7: krakowski | G7: grójecki | H7: namysłowski | I7: kolbuszowski | J7: kolneński | K7: kościerski | L7: kłobucki | M7: opatowski | N7: giżycki | O7: jarociński | P7: gryfiński | T7: Lipiec | U7: 2025
A8: kamiennogórski | B8: inowrocławski | C8: kraśnicki | D8: sulęciński | E8: opoczyński | F8: limanowski | G8: kozienicki | H8: nyski | I8: krośnieński | J8: łomżyński | K8: kwidzyński | L8: lubliniecki | M8: ostrowiecki | N8: iławski | O8: kaliski | P8: kamieński | T8: Sierpień | U8: 2026
A9: kłodzki | B9: lipnowski | C9: lubartowski | D9: świebodziński | E9: pabianicki | F9: miechowski | G9: legionowski | H9: oleski | I9: leżajski | J9: moniecki | K9: lęborski | L9: mikołowski | M9: pińczowski | N9: kętrzyński | O9: kępiński | P9: kołobrzeski | T9: Wrzesień | U9: 2027
A10: legnicki | B10: mogileński | C10: lubelski | D10: zielonogórski | E10: pajęczański | F10: myślenicki | G10: lipski | H10: opolski | I10: lubaczowski | J10: sejneński | K10: malborski | L10: myszkowski | M10: sandomierski | N10: lidzbarski | O10: kolski | P10: koszaliński | T10: Październik | U10: 2028
A11: lubański | B11: nakielski | C11: łęczyński | D11: żagański | E11: piotrkowski | F11: nowosądecki | G11: łosicki | H11: prudnicki | I11: łańcucki | J11: siemiatycki | K11: nowodworski | L11: pszczyński | M11: skarżyski | N11: mrągowski | O11: koniński | P11: myśliborski | T11: Listopad | U11: 2029
A12: lubiński | B12: radziejowski | C12: łukowski | D12: żarski | E12: poddębicki | F12: nowotarski | G12: makowski | H12: strzelecki | I12: mielecki | J12: sokólski | K12: pucki | L12: raciborski | M12: starachowicki | N12: nidzicki | O12: kościański | P12: policki | T12: Grudzień | U12: 2030
A13: lwówecki | B13: rypiński | C13: opolski | D13: wschowski | E13: radomszczański | F13: olkuski | G13: miński | H13: m. Opole | I13: niżański | J13: suwalski | K13: słupski | L13: rybnicki | M13: staszowski | N13: nowomiejski | O13: krotoszyński | P13: pyrzycki | U13: 2031
A14: milicki | B14: sępoleński | C14: parczewski | D14: m. Gorzów Wielkopolski | E14: rawski | F14: oświęcimski | G14: mławski | I14: przemyski | J14: wysokomazowiecki | K14: starogardzki | L14: tarnogórski | M14: włoszczowski | N14: olecki | O14: leszczyński | P14: sławieński | U14: 2032
A15: oleśnicki | B15: świecki | C15: puławski | D15: m. Zielona Góra | E15: sieradzki | F15: proszowicki | G15: nowodworski | I15: przeworski | J15: zambrowski | K15: tczewski | L15: bieruńsko-lędziński | M15: m. Kielce | N15: olsztyński | O15: międzychodzki | P15: stargardzki | U15: 2033
A16: oławski | B16: toruński | C16: radzyński | E16: skierniewicki | F16: suski | G16: ostrołęcki | I16: ropczycko-sędziszowski | J16: m. Białystok | K16: wejherowski | L16: wodzisławski | N16: ostródzki | O16: nowotomyski | P16: szczecinecki | U16: 2034
A17: polkowicki | B17: tucholski | C17: rycki | E17: tomaszowski | F17: tarnowski | G17: ostrowski | I17: rzeszowski | J17: m. Łomża | K17: sztumski | L17: zawierciański | N17: piski | O17: obornicki | P17: świdwiński | U17: 2035
A18: strzeliński | B18: wąbrzeski | C18: świdnicki | E18: wieluński | F18: tatrzański | G18: otwocki | I18: sanocki | J18: m. Suwałki | K18: m. Gdańsk | L18: żywiecki | N18: szczycieński | O18: ostrowski | P18: wałecki | U18: 2036
A19: średzki | B19: włocławski | C19: tomaszowski | E19: wieruszowski | F19: wadowicki | G19: piaseczyński | I19: stalowowolski | K19: m. Gdynia | L19: m. Bielsko-Biała | N19: gołdapski | O19: ostrzeszowski | P19: łobeski
A20: świdnicki | B20: żniński | C20: włodawski | E20: zduńskowolski | F20: wielicki | G20: płocki | I20: strzyżowski | K20: m. Słupsk | L20: m. Bytom | N20: węgorzewski | O20: pilski | P20: m. Koszalin
A21: trzebnicki | B21: m. Bydgoszcz | C21: zamojski | E21: zgierski | F21: m. Kraków | G21: płoński | I21: tarnobrzeski | K21: m. Sopot | L21: m. Chorzów | N21: m. Elbląg | O21: pleszewski | P21: m. Szczecin
A22: wałbrzyski | B22: m. Grudziądz | C22: m. Biała Podlaska | E22: brzeziński | F22: m. Nowy Sącz | G22: pruszkowski | I22: leski | L22: m. Częstochowa | N22: m. Olsztyn | O22: poznański | P22: m. Świnoujście
A23: wołowski | B23: m. Toruń | C23: m. Chełm | E23: m. Łódź | F23: m. Tarnów | G23: przasnyski | I23: m. Krosno | L23: m. Dąbrowa Górnicza | O23: rawicki
A24: wrocławski | B24: m. Włocławek | C24: m. Lublin | E24: m. Piotrków Trybunalski | G24: przysuski | I24: m. Przemyśl | L24: m. Gliwice | O24: słupecki
A25: ząbkowicki | C25: m. Zamość | E25: m. Skierniewice | G25: pułtuski | I25: m. Rzeszów | L25: m. Jastrzębie-Zdrój | O25: szamotulski
A26: zgorzelecki | G26: radomski | I26: m. Tarnobrzeg | L26: m. Jaworzno | O26: średzki
A27: złotoryjski | G27: siedlecki | L27: m. Katowice | O27: śremski
A28: m. Jelenia Góra | G28: sierpecki | L28: m. Mysłowice | O28: turecki
A29: m. Legnica | G29: sochaczewski | L29: m. Piekary Śląskie | O29: wągrowiecki
A30: m. Wrocław | G30: sokołowski | L30: m. Ruda Śląska | O30: wolsztyński
A31: m. Wałbrzych | G31: szydłowiecki | L31: m. Rybnik | O31: wrzesiński
G32: warszawski zachodni | L32: m. Siemianowice Śląskie | O32: złotowski
G33: węgrowski | L33: m. Sosnowiec | O33: m. Kalisz
G34: wołomiński | L34: m. Świętochłowice | O34: m. Konin
G35: wyszkowski | L35: m. Tychy | O35: m. Leszno
G36: zwoleński | L36: m. Zabrze | O36: m. Poznań
G37: żuromiński | L37: m. Żory
G38: żyrardowski
G39: m. Ostrołęka
G40: m. Płock
...
